<sdf version="1.9">
  <model name="blueboat">
    <link name="base_link">
      <inertial>
        <pose>-0.05 0 -0.15 0 0 0</pose>
        <mass>30.0</mass>
        <inertia>
          <ixx>2.42369</ixx>
          <ixy>0</ixy>
          <ixz>0</ixz>
          <iyy>3.9235025</iyy>
          <iyz>0</iyz>
          <izz>5.6403125</izz>
        </inertia>
      </inertial>
      <collision name="hull_collision">
        <geometry>
          <mesh>
            <uri>models://blueboat/meshes/blueboat_hull_collision.stl</uri>
          </mesh>
        </geometry>
      </collision>
      <collision name="pontoon_port_collision">
        <pose>0 0.295 0.008 0 0 0</pose>
        <geometry>
          <box>
            <size>1.2 0.15 0.18</size>
          </box>
        </geometry>
      </collision>
      <collision name="pontoon_stbd_collision">
        <pose>0 -0.295 0.008 0 0 0</pose>
        <geometry>
          <box>
            <size>1.2 0.15 0.18</size>
          </box>
        </geometry>
      </collision>
      <visual name="hull_visual">
        <geometry>
          <mesh>
            <uri>models://blueboat/meshes/blueboat_hull.dae</uri>
          </mesh>
        </geometry>
        <material>
          <diffuse>0 0 1 1</diffuse>
          <ambient>1 0 1 1</ambient>
          <specular>0.7 0.7 0.7 1</specular>
          <pbr>
            <metal>
              <metalness>0.5</metalness>
              <roughness>0.5</roughness>
            </metal>
          </pbr>
        </material>
      </visual>
      <visual name="aerial_visual">
        <geometry>
          <mesh>
            <uri>models://blueboat/meshes/blueboat_aerial.dae</uri>
          </mesh>
        </geometry>
        <material>
          <diffuse>0.01 0.01 0.01 1</diffuse>
          <ambient>0.01 0.01 0.01 1</ambient>
          <specular>0.7 0.7 0.7 1</specular>
          <pbr>
            <metal>
              <metalness>0.5</metalness>
              <roughness>0.5</roughness>
            </metal>
          </pbr>
        </material>
      </visual>
      <visual name="crosstube_visual">
        <geometry>
          <mesh>
            <uri>models://blueboat/meshes/blueboat_crosstube.dae</uri>
          </mesh>
        </geometry>
        <material>
          <diffuse>0.01 0.01 0.01 1</diffuse>
          <ambient>0.01 0.01 0.01 1</ambient>
          <specular>0.7 0.7 0.7 1</specular>
          <pbr>
            <metal>
              <metalness>0.5</metalness>
              <roughness>0.5</roughness>
            </metal>
          </pbr>
        </material>
      </visual>
      <visual name="flag_visual">
        <geometry>
          <mesh>
            <uri>models://blueboat/meshes/blueboat_flag.dae</uri>
          </mesh>
        </geometry>
        <material>
          <diffuse>1 1 0 1</diffuse>
          <ambient>1 1 0 1</ambient>
          <specular>0.7 0.7 0.7 1</specular>
          <pbr>
            <metal>
              <metalness>0.5</metalness>
              <roughness>0.5</roughness>
            </metal>
          </pbr>
        </material>
      </visual>
      <visual name="frame_asm_fore_visual">
        <geometry>
          <mesh>
            <uri>models://blueboat/meshes/blueboat_frame_asm_fore.dae</uri>
          </mesh>
        </geometry>
        <material>
          <diffuse>0.01 0.01 0.01 1</diffuse>
          <ambient>0.01 0.01 0.01 1</ambient>
          <specular>0.7 0.7 0.7 1</specular>
          <pbr>
            <metal>
              <metalness>0.9</metalness>
              <roughness>0.1</roughness>
            </metal>
          </pbr>
        </material>
      </visual>
      <visual name="frame_asm_aft_visual">
        <geometry>
          <mesh>
            <uri>models://blueboat/meshes/blueboat_frame_asm_aft.dae</uri>
          </mesh>
        </geometry>
        <material>
          <diffuse>0.01 0.01 0.01 1</diffuse>
          <ambient>0.01 0.01 0.01 1</ambient>
          <specular>0.7 0.7 0.7 1</specular>
          <pbr>
            <metal>
              <metalness>0.9</metalness>
              <roughness>0.1</roughness>
            </metal>
          </pbr>
        </material>
      </visual>
      <visual name="hatch_asm_stbd">
        <geometry>
          <mesh>
            <uri>models://blueboat/meshes/blueboat_hatch_asm_stbd.dae</uri>
          </mesh>
        </geometry>
        <material>
          <diffuse>0.01 0.01 0.01 1</diffuse>
          <ambient>0.01 0.01 0.01 1</ambient>
          <specular>0.7 0.7 0.7 1</specular>
          <pbr>
            <metal>
              <metalness>0.5</metalness>
              <roughness>0.5</roughness>
            </metal>
          </pbr>
        </material>
      </visual>
      <visual name="hatch_asm_port">
        <geometry>
          <mesh>
            <uri>models://blueboat/meshes/blueboat_hatch_asm_port.dae</uri>
          </mesh>
        </geometry>
        <material>
          <diffuse>0.01 0.01 0.01 1</diffuse>
          <ambient>0.01 0.01 0.01 1</ambient>
          <specular>0.7 0.7 0.7 1</specular>
          <pbr>
            <metal>
              <metalness>0.5</metalness>
              <roughness>0.5</roughness>
            </metal>
          </pbr>
        </material>
      </visual>
      <visual name="motor_stbd_visual">
        <geometry>
          <mesh>
            <uri>models://blueboat/meshes/blueboat_motor_stbd.dae</uri>
          </mesh>
        </geometry>
        <material>
          <diffuse>0.01 0.01 0.01 1</diffuse>
          <ambient>0.01 0.01 0.01 1</ambient>
          <specular>0.7 0.7 0.7 1</specular>
          <pbr>
            <metal>
              <metalness>0.5</metalness>
              <roughness>0.5</roughness>
            </metal>
          </pbr>
        </material>
      </visual>
      <visual name="motor_port_visual">
        <geometry>
          <mesh>
            <uri>models://blueboat/meshes/blueboat_motor_port.dae</uri>
          </mesh>
        </geometry>
        <material>
          <diffuse>0.01 0.01 0.01 1</diffuse>
          <ambient>0.01 0.01 0.01 1</ambient>
          <specular>0.7 0.7 0.7 1</specular>
          <pbr>
            <metal>
              <metalness>0.5</metalness>
              <roughness>0.5</roughness>
            </metal>
          </pbr>
        </material>
      </visual>
    </link>

    <link name="motor_stbd_link">
      <pose degrees="true">-0.488 -0.295 -0.272 -90 0 90</pose>
      <inertial>
        <mass>0.2</mass>
        <inertia>
          <ixx>0.1</ixx>
          <ixy>0</ixy>
          <ixz>0</ixz>
          <iyy>0.1</iyy>
          <iyz>0</iyz>
          <izz>0.1</izz>
        </inertia>
      </inertial>
      <collision name="prop_collision">
        <geometry>
          <mesh>
            <uri>models://blueboat/meshes/blueboat_prop_stbd.dae</uri>
          </mesh>
        </geometry>
      </collision>
      <visual name="prop_visual">
        <geometry>
          <mesh>
            <uri>models://blueboat/meshes/blueboat_prop_stbd.dae</uri>
          </mesh>
        </geometry>
        <material>
          <diffuse>0.01 0.01 0.01 1</diffuse>
          <ambient>0.01 0.01 0.01 1</ambient>
          <specular>0.7 0.7 0.7 1</specular>
          <pbr>
            <metal>
              <metalness>0.5</metalness>
              <roughness>0.5</roughness>
            </metal>
          </pbr>
        </material>
      </visual>
    </link>
    <joint name="motor_stbd_joint" type="revolute">
      <parent>base_link</parent>
      <child>motor_stbd_link</child>
      <axis>
        <xyz>0 0 -1</xyz>
        <limit>
          <lower>-1e16</lower>
          <upper>1e16</upper>
        </limit>
        <dynamics>
          <damping>0.02</damping>
        </dynamics>
      </axis>
    </joint>

    <link name="motor_port_link">
      <pose degrees="true">-0.488 0.295 -0.272 -90 0 90</pose>
      <inertial>
        <mass>0.2</mass>
        <inertia>
          <ixx>0.1</ixx>
          <ixy>0</ixy>
          <ixz>0</ixz>
          <iyy>0.1</iyy>
          <iyz>0</iyz>
          <izz>0.1</izz>
        </inertia>
      </inertial>
      <collision name="prop_collision">
        <geometry>
          <mesh>
            <uri>models://blueboat/meshes/blueboat_prop_port.dae</uri>
          </mesh>
        </geometry>
      </collision>
      <visual name="prop_visual">
        <geometry>
          <mesh>
            <uri>models://blueboat/meshes/blueboat_prop_port.dae</uri>
          </mesh>
        </geometry>
        <material>
          <diffuse>0.01 0.01 0.01 1</diffuse>
          <ambient>0.01 0.01 0.01 1</ambient>
          <specular>0.7 0.7 0.7 1</specular>
          <pbr>
            <metal>
              <metalness>0.5</metalness>
              <roughness>0.5</roughness>
            </metal>
          </pbr>
        </material>
      </visual>
    </link>
    <joint name="motor_port_joint" type="revolute">
      <parent>base_link</parent>
      <child>motor_port_link</child>
      <axis>
        <xyz>0 0 -1</xyz>
        <limit>
          <lower>-1e16</lower>
          <upper>1e16</upper>
        </limit>
        <dynamics>
          <damping>0.02</damping>
        </dynamics>
      </axis>
    </joint>

    <!-- sensors -->
    <link name="imu_link">
      <inertial>
        <pose>0 0 0 0 0 0</pose>
        <mass>0.1</mass>
        <inertia>
          <ixx>0.0001</ixx>
          <ixy>0</ixy>
          <ixz>0</ixz>
          <iyy>0.0001</iyy>
          <iyz>0</iyz>
          <izz>0.0001</izz>
        </inertia>
      </inertial>
      <sensor name="imu_sensor" type="imu">
        <pose degrees="true">0 0 0 180 0 0</pose>
        <always_on>1</always_on>
        <update_rate>1000.0</update_rate>
      </sensor>
    </link>
    <joint name="imu_joint" type="revolute">
      <child>imu_link</child>
      <parent>base_link</parent>
      <axis>
        <xyz>0 0 1</xyz>
        <limit>
          <lower>0</lower>
          <upper>0</upper>
        </limit>
        <dynamics>
          <damping>1.0</damping>
        </dynamics>
      </axis>
    </joint>


    <!-- NavSat -->

    <link name="navsat_link">
      <pose>0 0 0.05 0 0 0</pose>
      <inertial>
        <mass>0.1</mass>
        <inertia>
          <ixx>0.0001</ixx>
          <ixy>0</ixy>
          <ixz>0</ixz>
          <iyy>0.0001</iyy>
          <iyz>0</iyz>
          <izz>0.0001</izz>
        </inertia>
      </inertial>
      <sensor name="navsat_sensor" type="navsat">
        <pose>0 0 0 0 0 0</pose>
        <always_on>1</always_on>
        <update_rate>1.0</update_rate>
        <topic>navsat</topic>
        <gps>
          <fix>
            <service>1</service>
            <status>0</status>
          </fix>
        </gps>
      </sensor>
    </link>
    <joint name="navsat_joint" type="fixed">
      <parent>imu_link</parent>
      <child>navsat_link</child>
    </joint>

    <plugin
        filename="gz-sim-hydrodynamics-system"
        name="gz::sim::systems::Hydrodynamics">
      <link_name>base_link</link_name>
      <water_density>1000.0</water_density>
      <disable_added_mass>true</disable_added_mass>
      <disable_coriolis>true</disable_coriolis>
      <!-- First order stability derivative: -->
      <xU>0</xU>
      <yV>0</yV>
      <zW>0</zW>
      <kP>0</kP>
      <mQ>0</mQ>
      <nR>0</nR>
      <!-- Second order stability derivative: -->
      <xUabsU>-58.42</xUabsU>
      <yVabsV>-55.137</yVabsV>
      <zWabsW>-50.0</zWabsW>
      <kPabsP>-50</kPabsP>
      <mQabsQ>-50</mQabsQ>
      <nRabsR>-50</nRabsR>
    </plugin>

    <!-- plugins -->
    <plugin name="gz::sim::systems::JointStatePublisher"
      filename="gz-sim-joint-state-publisher-system">
    </plugin>
    <plugin name="gz::sim::systems::OdometryPublisher"
      filename="gz-sim-odometry-publisher-system">
      <odom_frame>odom</odom_frame>
      <robot_base_frame>base_link</robot_base_frame>
      <dimensions>3</dimensions>
    </plugin>

    <!-- left motor thruster cw -->
    <plugin name="gz::sim::systems::Thruster"
      filename="gz-sim-thruster-system">
      <namespace>blueboat</namespace>
      <joint_name>motor_port_joint</joint_name>
      <thrust_coefficient>-0.02</thrust_coefficient>
      <fluid_density>1025</fluid_density>
      <propeller_diameter>0.112</propeller_diameter>
      <velocity_control>0</velocity_control>
      <use_angvel_cmd>0</use_angvel_cmd>
    </plugin>

    <!-- right motor thruster ccw -->
    <plugin name="gz::sim::systems::Thruster"
      filename="gz-sim-thruster-system">
      <namespace>blueboat</namespace>
      <joint_name>motor_stbd_joint</joint_name>
      <thrust_coefficient>0.02</thrust_coefficient>
      <fluid_density>1025</fluid_density>
      <propeller_diameter>0.112</propeller_diameter>
      <velocity_control>0</velocity_control>
      <use_angvel_cmd>0</use_angvel_cmd>
    </plugin>

 

  </model>
</sdf>
