<sdf version='1.11'>
  <model name='pipe_model'>
    <static>1</static>
    <link name='pipe_base_link'>
      <inertial>
        <pose>0 0 0 0 0 0</pose>
        <mass>235.4152162093547</mass>
        <inertia>
          <ixx>533.8067881323725</ixx>
          <ixy>1.5948978886996961e-13</ixy>
          <ixz>-444.4643834093107</ixz>
          <iyy>1033.1685999307199</iyy>
          <iyz>2.3032939573935558e-13</iyz>
          <izz>504.90262862240178</izz>
        </inertia>
      </inertial>
     
      <collision name='pipe_base_link_collision'>
        <pose>0 0 0 0 0 0</pose>
        <geometry>
          <box>
            <size>5 1 3</size>
          </box>
        </geometry>
      </collision>

      
      <visual name='pipe_base_link_visual'>
        <pose>0 0 0 0 0 0</pose>
        <geometry>
          <mesh>
            <scale>1 1 1</scale>
            <uri>model://robotx26/pipe_task/meshes/pipe_base_link.STL</uri>
          </mesh>
        </geometry>
        <material>
          <diffuse>0.813725531 0.774509847 0.735294163 1</diffuse>
          <ambient>0.813725531 0.774509847 0.735294163 1</ambient>
        </material>
      </visual>
      <visual name='pipe_base_link_fixed_joint_lump__pipe_1_link_visual_1'>
        <pose>0 0 0 0 0 0</pose>
        <geometry>
          <mesh>
            <scale>1 1 1</scale>
            <uri>model://robotx26/pipe_task/meshes/pipe_1_link.STL</uri>
          </mesh>
        </geometry>
        <material>
          <diffuse>0.813725531 0.774509847 0.735294163 1</diffuse>
          <ambient>0.813725531 0.774509847 0.735294163 1</ambient>
        </material>
      </visual>
      <visual name='pipe_base_link_fixed_joint_lump__pipe_2_link_visual_2'>
        <pose>0 0 0 0 0 0</pose>
        <geometry>
          <mesh>
            <scale>1 1 1</scale>
            <uri>model://robotx26/pipe_task/meshes/pipe_2_link.STL</uri>
          </mesh>
        </geometry>
        <material>
          <diffuse>0.813725531 0.774509847 0.735294163 1</diffuse>
          <ambient>0.813725531 0.774509847 0.735294163 1</ambient>
        </material>
      </visual>
      <visual name='pipe_base_link_fixed_joint_lump__pipe_3_link_visual_3'>
        <pose>0 0 0 0 0 0</pose>
        <geometry>
          <mesh>
            <scale>1 1 1</scale>
            <uri>model://robotx26/pipe_task/meshes/pipe_3_link.STL</uri>
          </mesh>
        </geometry>
        <material>
          <diffuse>0.813725531 0.774509847 0.735294163 1</diffuse>
          <ambient>0.813725531 0.774509847 0.735294163 1</ambient>
        </material>
      </visual>
      <visual name='pipe_base_link_fixed_joint_lump__pipe_4_link_visual_4'>
        <pose>0 0 0 0 0 0</pose>
        <geometry>
          <mesh>
            <scale>1 1 1</scale>
            <uri>model://robotx26/pipe_task/meshes/pipe_4_link.STL</uri>
          </mesh>
        </geometry>
        <material>
          <diffuse>0.813725531 0.774509847 0.735294163 1</diffuse>
          <ambient>0.813725531 0.774509847 0.735294163 1</ambient>
        </material>
      </visual>
      <visual name='pipe_base_link_fixed_joint_lump__pipe_5_link_visual_5'>
        <pose>0 0 0 0 0 0</pose>
        <geometry>
          <mesh>
            <scale>1 1 1</scale>
            <uri>model://robotx26/pipe_task/meshes/pipe_5_link.STL</uri>
          </mesh>
        </geometry>
        <material>
          <diffuse>0.813725531 0.774509847 0.735294163 1</diffuse>
          <ambient>0.813725531 0.774509847 0.735294163 1</ambient>
        </material>
      </visual>
      <visual name='pipe_base_link_fixed_joint_lump__pipe_connector_1_visual_6'>
        <pose>0 0 0 0 0 0</pose>
        <geometry>
          <mesh>
            <scale>1 1 1</scale>
            <uri>model://robotx26/pipe_task/meshes/pipe_connector_1.STL</uri>
          </mesh>
        </geometry>
        <material>
          <diffuse>0.813725531 0.774509847 0.735294163 1</diffuse>
          <ambient>0.813725531 0.774509847 0.735294163 1</ambient>
        </material>
      </visual>
      <visual name='pipe_base_link_fixed_joint_lump__pipe_connector_2_visual_7'>
        <pose>0 0 0 0 0 0</pose>
        <geometry>
          <mesh>
            <scale>1 1 1</scale>
            <uri>model://robotx26/pipe_task/meshes/pipe_connector_2.STL</uri>
          </mesh>
        </geometry>
        <material>
          <diffuse>0.813725531 0.774509847 0.735294163 1</diffuse>
          <ambient>0.813725531 0.774509847 0.735294163 1</ambient>
        </material>
      </visual>
      <visual name='pipe_base_link_fixed_joint_lump__pipe_connector_6_visual_8'>
        <pose>0 0 0 0 0 0</pose>
        <geometry>
          <mesh>
            <scale>1 1 1</scale>
            <uri>model://robotx26/pipe_task/meshes/pipe_connector_6.STL</uri>
          </mesh>
        </geometry>
        <material>
          <diffuse>0.813725531 0.774509847 0.735294163 1</diffuse>
          <ambient>0.813725531 0.774509847 0.735294163 1</ambient>
        </material>
      </visual>
    </link>
    <joint name='pipe_connector_3_joint' type='revolute'>
      <pose relative_to='pipe_base_link'>0 0 0 0 0 0</pose>
      <parent>pipe_base_link</parent>
      <child>pipe_connector_3</child>
      <axis>
        <xyz>0 0 1</xyz>
        <limit>
          <lower>-inf</lower>
          <upper>inf</upper>
        </limit>
        <dynamics>
          <spring_reference>0</spring_reference>
          <spring_stiffness>0</spring_stiffness>
        </dynamics>
      </axis>
    </joint>
    <link name='pipe_connector_3'>
      <pose relative_to='pipe_connector_3_joint'>0 0 0 0 0 0</pose>
      <inertial>
        <pose>-2.5869474871687101 4.7741754271927999e-16 -0.93694748716871601 0 0 0</pose>
        <mass>12.4995538301383</mass>
        <inertia>
          <ixx>0.27530348734369697</ixx>
          <ixy>5.9506478125894599e-31</ixy>
          <ixz>-8.3510227896741498e-16</ixz>
          <iyy>0.27530348734369697</iyy>
          <iyz>-1.8146406410373201e-16</iyz>
          <izz>0.52996828941413698</izz>
        </inertia>
      </inertial>
      
      <visual name='pipe_connector_3_visual'>
        <pose>0 0 0 0 0 0</pose>
        <geometry>
          <mesh>
            <scale>1 1 1</scale>
            <uri>model://robotx26/pipe_task/meshes/pipe_connector_3.STL</uri>
          </mesh>
        </geometry>
        <material>
          <diffuse>0.813725531 0.774509847 0.735294163 1</diffuse>
          <ambient>0.813725531 0.774509847 0.735294163 1</ambient>
        </material>
      </visual>
    </link>
    <joint name='pipe_connector_4_joint' type='revolute'>
      <pose relative_to='pipe_base_link'>0 0 0 0 0 0</pose>
      <parent>pipe_base_link</parent>
      <child>pipe_connector_4</child>
      <axis>
        <xyz>0 0 1</xyz>
        <limit>
          <lower>-inf</lower>
          <upper>inf</upper>
        </limit>
        <dynamics>
          <spring_reference>0</spring_reference>
          <spring_stiffness>0</spring_stiffness>
        </dynamics>
      </axis>
    </joint>
    <link name='pipe_connector_4'>
      <pose relative_to='pipe_connector_4_joint'>0 0 0 0 0 0</pose>
      <inertial>
        <pose>-2.5869474871687101 2.20188488356558e-15 -2.5369474871687201 0 0 0</pose>
        <mass>12.4995538301383</mass>
        <inertia>
          <ixx>0.27530348734369697</ixx>
          <ixy>1.5350786682656099e-31</ixy>
          <ixz>-7.3777723097587097e-16</ixz>
          <iyy>0.27530348734369697</iyy>
          <iyz>-9.3262648609302703e-17</iyz>
          <izz>0.52996828941413798</izz>
        </inertia>
      </inertial>
      
      <visual name='pipe_connector_4_visual'>
        <pose>0 0 0 0 0 0</pose>
        <geometry>
          <mesh>
            <scale>1 1 1</scale>
            <uri>model://robotx26/pipe_task/meshes/pipe_connector_4.STL</uri>
          </mesh>
        </geometry>
        <material>
          <diffuse>0.813725531 0.774509847 0.735294163 1</diffuse>
          <ambient>0.813725531 0.774509847 0.735294163 1</ambient>
        </material>
      </visual>
    </link>
    <joint name='pipe_connector_5_joint' type='revolute'>
      <pose relative_to='pipe_base_link'>0 0 0 0 0 0</pose>
      <parent>pipe_base_link</parent>
      <child>pipe_connector_5</child>
      <axis>
        <xyz>1 0 0</xyz>
        <limit>
          <lower>-inf</lower>
          <upper>inf</upper>
        </limit>
        <dynamics>
          <spring_reference>0</spring_reference>
          <spring_stiffness>0</spring_stiffness>
        </dynamics>
      </axis>
    </joint>
    <link name='pipe_connector_5'>
      <pose relative_to='pipe_connector_5_joint'>0 0 0 0 0 0</pose>
      <inertial>
        <pose>-3.5238949743374199 1.1362014102000099e-15 -3.4738949743374299 0 0 0</pose>
        <mass>12.4995538301383</mass>
        <inertia>
          <ixx>0.52996828941413798</ixx>
          <ixy>3.8016432574970799e-32</ixy>
          <ixz>-3.13037650002783e-17</ixz>
          <iyy>0.27530348734369697</iyy>
          <iyz>-2.7343210111373901e-34</iyz>
          <izz>0.27530348734369697</izz>
        </inertia>
      </inertial>
      
      <visual name='pipe_connector_5_visual'>
        <pose>0 0 0 0 0 0</pose>
        <geometry>
          <mesh>
            <scale>1 1 1</scale>
            <uri>model://robotx26/pipe_task/meshes/pipe_connector_5.STL</uri>
          </mesh>
        </geometry>
        <material>
          <diffuse>0.813725531 0.774509847 0.735294163 1</diffuse>
          <ambient>0.813725531 0.774509847 0.735294163 1</ambient>
        </material>
      </visual>



    </link>


    <include>
      <name>pipe_led_1</name>
      <uri>model://robotx26/pipe_led</uri>
      <pose relative_to='pipe_base_link'>-1 -0.1 0 0 0 0</pose>

    </include>

    <include>
      <name>pipe_led_2</name>
      <uri>model://robotx26/pipe_led</uri>
      <pose relative_to='pipe_connector_3'>-2.4 -0.1 -0.3 0 0 0</pose>

    </include>

    <include>
      <name>pipe_led_3</name>
      <uri>model://robotx26/pipe_led</uri>
      <pose relative_to='pipe_connector_3'>-2.6 -0.1 -1.75 0 0 0</pose>

    </include>

    <include>
      <name>pipe_led_4</name>
      <uri>model://robotx26/pipe_led</uri>
      <pose relative_to='pipe_connector_4'>-2.8 -0.1 -3.05 0 0 0</pose>

    </include>

    <include>
      <name>pipe_led_5</name>
      <uri>model://robotx26/pipe_led</uri>
      <pose relative_to='pipe_connector_5'>-4.35 -0.1 -3.45 0 0 0</pose>

    </include>


    <frame name='pipe_1_joint' attached_to='pipe_base_link'>
      <pose>0 0 0 0 0 0</pose>
    </frame>
    <frame name='pipe_1_link' attached_to='pipe_1_joint'>
      <pose>0 0 0 0 0 0</pose>
    </frame>
    <frame name='pipe_2_joint' attached_to='pipe_base_link'>
      <pose>0 0 0 0 0 0</pose>
    </frame>
    <frame name='pipe_2_link' attached_to='pipe_2_joint'>
      <pose>0 0 0 0 0 0</pose>
    </frame>
    <frame name='pipe_3_joint' attached_to='pipe_base_link'>
      <pose>0 0 0 0 0 0</pose>
    </frame>
    <frame name='pipe_3_link' attached_to='pipe_3_joint'>
      <pose>0 0 0 0 0 0</pose>
    </frame>
    <frame name='pipe_4_joint' attached_to='pipe_base_link'>
      <pose>0 0 0 0 0 0</pose>
    </frame>
    <frame name='pipe_4_link' attached_to='pipe_4_joint'>
      <pose>0 0 0 0 0 0</pose>
    </frame>
    <frame name='pipe_5_joint' attached_to='pipe_base_link'>
      <pose>0 0 0 0 0 0</pose>
    </frame>
    <frame name='pipe_5_link' attached_to='pipe_5_joint'>
      <pose>0 0 0 0 0 0</pose>
    </frame>
    <frame name='pipe_connector_1_joint' attached_to='pipe_base_link'>
      <pose>0 0 0 0 0 0</pose>
    </frame>
    <frame name='pipe_connector_1' attached_to='pipe_connector_1_joint'>
      <pose>0 0 0 0 0 0</pose>
    </frame>
    <frame name='pipe_connector_2_joint' attached_to='pipe_base_link'>
      <pose>0 0 0 0 0 0</pose>
    </frame>
    <frame name='pipe_connector_2' attached_to='pipe_connector_2_joint'>
      <pose>0 0 0 0 0 0</pose>
    </frame>
    <frame name='pipe_connector_6_joint' attached_to='pipe_base_link'>
      <pose>0 0 0 0 0 0</pose>
    </frame>
    <frame name='pipe_connector_6' attached_to='pipe_connector_6_joint'>
      <pose>0 0 0 0 0 0</pose>
    </frame>
  </model>
</sdf>